<?xml version="1.0"?>
<sdf version="1.8">
  <model name="spot">
    <link name="base_link">
      <inertial>
        <pose>0.005937 0.000326 0.04636 0 -0 0</pose>
        <mass>20.492</mass>
        <inertia>
          <ixx>0.287877</ixx>
          <ixy>0.0014834</ixy>
          <ixz>-0.0347842</ixz>
          <iyy>1.31868</iyy>
          <iyz>-0.000519074</iyz>
          <izz>1.18915</izz>
        </inertia>
      </inertial>
      <collision name="base_link_collision">
        <geometry>
          <mesh>
            <uri>package://spot_description/models/spot/meshes/body_collision.stl</uri>
          </mesh>
        </geometry>
      </collision>
      <visual name="base_link_visual">
        <geometry>
          <mesh>
            <uri>package://spot_description/models/spot/meshes/body.dae</uri>
          </mesh>
        </geometry>
      </visual>
      <self_collide>0</self_collide>
    </link>
    <link name="body">
      <inertial>
        <mass>1e-05</mass>
        <inertia>
          <ixx>0.001</ixx>
          <ixy>1e-06</ixy>
          <ixz>1e-06</ixz>
          <iyy>0.001</iyy>
          <iyz>1e-06</iyz>
          <izz>0.001</izz>
        </inertia>
      </inertial>
    </link>
    <joint name="base_link_joint" type="fixed">
      <child>body</child>
      <parent>base_link</parent>
      <axis>
        <dynamics>
          <spring_reference>0</spring_reference>
          <spring_stiffness>0</spring_stiffness>
        </dynamics>
        <xyz>0 0 1</xyz>
        <limit>
          <lower>-1e+16</lower>
          <upper>1e+16</upper>
        </limit>
      </axis>
      <physics>
        <ode>
          <limit>
            <cfm>0</cfm>
            <erp>0.2</erp>
          </limit>
        </ode>
      </physics>
    </joint>
    <link name="front_rail">
      <pose>0.223 0 0.0805 0 -0 0</pose>
      <inertial>
        <mass>1e-05</mass>
        <inertia>
          <ixx>0.001</ixx>
          <ixy>1e-06</ixy>
          <ixz>1e-06</ixz>
          <iyy>0.001</iyy>
          <iyz>1e-06</iyz>
          <izz>0.001</izz>
        </inertia>
      </inertial>
    </link>

    <link name="lidar_base_link">
      <pose>0.223 0 0.0805 0 0 0</pose>
      <collision name="collision">
        <pose>0 0 0.03585 0 0 0</pose>
        <geometry>
          <cylinder>
            <radius>0.0516</radius>
            <length>0.0717</length>
          </cylinder>
        </geometry>
      </collision>
      <visual name="visual">
        <geometry>
          <mesh>
            <uri>package://spot_description/models/spot/meshes/lidar_3d_v1.dae</uri>
          </mesh>
        </geometry>
      </visual>
    </link>

    <link name="camera_base_link">
      <pose>-0.223 0 0.183 0 -0 0</pose>
      <collision name="payload_base">
        <geometry>
          <mesh>
            <uri>package://spot_description/models/spot/meshes/PPV4_Sim_Base.STL</uri>
          </mesh>
        </geometry>
      </collision>
      <visual name="payload_base">
        <geometry>
          <mesh>
            <uri>package://spot_description/models/spot/meshes/PPV4_Sim_Base.STL</uri>
          </mesh>
        </geometry>
        <material>
          <ambient>0 0 0 1</ambient>
          <diffuse>0.5 0.5 0.5 1</diffuse>
          <specular>1 1 1 1</specular>
          <emissive>0 0 0 0</emissive>
        </material>
      </visual>
      <collision name="payload_birdcage">
        <geometry>
          <mesh>
            <uri>package://spot_description/models/spot/meshes/birdcage.STL</uri>
          </mesh>
        </geometry>
      </collision>
      <visual name="payload_birdcage">
        <geometry>
          <mesh>
            <uri>package://spot_description/models/spot/meshes/birdcage.STL</uri>
          </mesh>
        </geometry>
        <material>
          <ambient>0.05 0.05 0.05 1</ambient>
          <diffuse>0.05 0.05 0.05 1</diffuse>
          <specular>0.05 0.05 0.05 1</specular>
          <emissive>0 0 0 0</emissive>
        </material>
      </visual>
    </link>

    <link name="lidar_link">
      <pose>0.223 0 0.11635 0 0 0</pose>
      <sensor name='gpu_lidar' type='gpu_lidar'>
        <topic>model/spot/lidar</topic>
        <update_rate>10</update_rate>
        <gz_frame_id>lidar_link</gz_frame_id>
        <lidar>
          <scan>
            <horizontal>
              <samples>1800</samples>
              <resolution>1</resolution>
              <min_angle>-3.14159</min_angle>
              <max_angle>3.14159</max_angle>
            </horizontal>
            <vertical>
              <samples>16</samples>
              <resolution>1</resolution>
              <min_angle>-0.261799</min_angle>
              <max_angle>0.261799</max_angle>
            </vertical>
          </scan>
          <range>
            <min>0.08</min>
            <max>100.0</max>
            <resolution>0.03</resolution>
          </range>
        </lidar>
        <alwaysOn>1</alwaysOn>
        <visualize>true</visualize>
      </sensor>
    </link>

    <link name="thermal_camera_link">
      <pose>-0.223 0 0.333 0 -0 0</pose>
      <visual name="visual">
        <geometry>
          <box>
            <size>0.05 0.05 0.05</size>
          </box>
        </geometry>
      </visual>
      <sensor name="thermal_camera" type="thermal">
        <geometry>
          <cylinder>
            <length>0.1</length>
            <radius>0.005</radius>
          </cylinder>
        </geometry>
        <camera>
          <horizontal_fov>0.8727</horizontal_fov>
          <image>
            <width>240</width>
            <height>240</height>
            <format>L16</format>
          </image>
          <clip>
            <near>0.1</near>
            <far>100</far>
          </clip>
        </camera>
        <always_on>1</always_on>
        <update_rate>30</update_rate>
        <visualize>true</visualize>
        <topic>model/spot/thermal_camera</topic>
      </sensor>
    </link>

    <joint name='lidar_base_joint' type='fixed'>
      <parent>front_rail</parent>
      <child>lidar_base_link</child>
    </joint>
    <joint name='lidar_joint' type='fixed'>
      <parent>lidar_base_link</parent>
      <child>lidar_link</child>
    </joint>

    <joint name='camera_base_joint' type='fixed'>
      <parent>rear_rail</parent>
      <child>camera_base_link</child>
    </joint>
    <joint name='thermal_camera_joint' type='fixed'>
      <parent>camera_base_link</parent>
      <child>thermal_camera_link</child>
    </joint>

    <joint name="front_rail_joint" type="fixed">
      <child>front_rail</child>
      <parent>body</parent>
      <axis>
        <dynamics>
          <spring_reference>0</spring_reference>
          <spring_stiffness>0</spring_stiffness>
        </dynamics>
        <xyz>0 0 1</xyz>
        <limit>
          <lower>-1e+16</lower>
          <upper>1e+16</upper>
        </limit>
      </axis>
      <physics>
        <ode>
          <limit>
            <cfm>0</cfm>
            <erp>0.2</erp>
          </limit>
        </ode>
      </physics>
    </joint>
    <link name="rear_rail">
      <pose>-0.223 0 0.0805 0 -0 0</pose>
      <inertial>
        <mass>1e-05</mass>
        <inertia>
          <ixx>0.001</ixx>
          <ixy>1e-06</ixy>
          <ixz>1e-06</ixz>
          <iyy>0.001</iyy>
          <iyz>1e-06</iyz>
          <izz>0.001</izz>
        </inertia>
      </inertial>
    </link>

    <joint name="rear_rail_joint" type="fixed">
      <child>rear_rail</child>
      <parent>body</parent>
      <axis>
        <dynamics>
          <spring_reference>0</spring_reference>
          <spring_stiffness>0</spring_stiffness>
        </dynamics>
        <xyz>0 0 1</xyz>
        <limit>
          <lower>-1e+16</lower>
          <upper>1e+16</upper>
        </limit>
      </axis>
      <physics>
        <ode>
          <limit>
            <cfm>0</cfm>
            <erp>0.2</erp>
          </limit>
        </ode>
      </physics>
    </joint>
    <link name="battery">
      <pose>0 0 -0.03 0 -0 0</pose>
      <inertial>
        <mass>4</mass>
        <inertia>
          <ixx>0.012291</ixx>
          <ixy>0</ixy>
          <ixz>0</ixz>
          <iyy>0.037875</iyy>
          <iyz>0</iyz>
          <izz>0.0444</izz>
        </inertia>
      </inertial>
      <collision name="battery_collision">
        <geometry>
          <box>
            <size>0.324 0.168 0.093</size>
          </box>
        </geometry>
      </collision>
      <visual name="battery_visual">
        <geometry>
          <box>
            <size>0.324 0.168 0.093</size>
          </box>
        </geometry>
        <material>
          <ambient>0.917647 0.654902 0 1</ambient>
          <diffuse>0.917647 0.654902 0 1</diffuse>
          <specular>0.917647 0.654902 0 1</specular>
          <emissive>0 0 0 0</emissive>
        </material>
      </visual>
    </link>
    <joint name="battery_joint" type="fixed">
      <child>battery</child>
      <parent>base_link</parent>
      <axis>
        <dynamics>
          <spring_reference>0</spring_reference>
          <spring_stiffness>0</spring_stiffness>
        </dynamics>
        <xyz>0 0 1</xyz>
        <limit>
          <lower>-1e+16</lower>
          <upper>1e+16</upper>
        </limit>
      </axis>
      <physics>
        <ode>
          <limit>
            <cfm>0</cfm>
            <erp>0.2</erp>
          </limit>
        </ode>
      </physics>
    </joint>
    <link name="camera_back">
      <pose>-0.425 0 0.01 -0 0.3 3.1415926535897931</pose>
      <inertial>
        <mass>1e-05</mass>
        <inertia>
          <ixx>0.001</ixx>
          <ixy>1e-06</ixy>
          <ixz>1e-06</ixz>
          <iyy>0.001</iyy>
          <iyz>1e-06</iyz>
          <izz>0.001</izz>
        </inertia>
      </inertial>
      <sensor name="back_fisheye_image" type="camera">
        <always_on>1</always_on>
        <update_rate>30</update_rate>
        <visualize>true</visualize>
        <topic>model/spot/camera/back_fisheye_image</topic>
        <visualize>true</visualize>
        <pose>0 0.01 0 0 -0 0</pose>
        <camera>
          <horizontal_fov>1.78634</horizontal_fov>
          <image>
            <width>640</width>
            <height>480</height>
            <format>R8G8B8</format>
          </image>
          <clip>
            <near>0.1</near>
            <far>20</far>
          </clip>
          <noise>
            <type>gaussian</type>
            <mean>0</mean>
            <stddev>0.007</stddev>
          </noise>
          <lens>
            <intrinsics>
              <fx>257.487</fx>
              <fy>257.487</fy>
              <cx>319.5</cx>
              <cy>239.5</cy>
              <s>0</s>
            </intrinsics>
            <type>stereographic</type>
            <scale_to_hfov>1</scale_to_hfov>
          </lens>
        </camera>
      </sensor>
      <sensor name="back_depth" type="depth_camera">
        <always_on>1</always_on>
        <update_rate>30</update_rate>
        <visualize>true</visualize>
        <topic>model/spot/camera/back_depth</topic>
        <visualize>true</visualize>
        <camera>
          <horizontal_fov>1.78634</horizontal_fov>
          <image>
            <width>424</width>
            <height>240</height>
            <format>R_FLOAT32</format>
          </image>
          <clip>
            <near>0.1</near>
            <far>4</far>
          </clip>
          <noise>
            <type>gaussian</type>
            <mean>0</mean>
            <stddev>0.007</stddev>
          </noise>
          <lens>
            <intrinsics>
              <fx>170.6</fx>
              <fy>170.6</fy>
              <cx>211.5</cx>
              <cy>119.5</cy>
              <s>0</s>
            </intrinsics>
            <type>stereographic</type>
            <scale_to_hfov>1</scale_to_hfov>
          </lens>
        </camera>
      </sensor>
    </link>
    <joint name="camera_back_j" type="fixed">
      <child>camera_back</child>
      <parent>base_link</parent>
      <axis>
        <dynamics>
          <spring_reference>0</spring_reference>
          <spring_stiffness>0</spring_stiffness>
        </dynamics>
        <xyz>0 0 1</xyz>
        <limit>
          <lower>-1e+16</lower>
          <upper>1e+16</upper>
        </limit>
      </axis>
      <physics>
        <ode>
          <limit>
            <cfm>0</cfm>
            <erp>0.2</erp>
          </limit>
        </ode>
      </physics>
    </joint>
    <link name="camera_frontleft">
      <pose>0.415 0.037 -0.01 1.35556 0.353917 -0.554196</pose>
      <inertial>
        <mass>1e-05</mass>
        <inertia>
          <ixx>0.001</ixx>
          <ixy>1e-06</ixy>
          <ixz>1e-06</ixz>
          <iyy>0.001</iyy>
          <iyz>1e-06</iyz>
          <izz>0.001</izz>
        </inertia>
      </inertial>
      <sensor name="frontleft_fisheye_image" type="camera">
        <always_on>1</always_on>
        <update_rate>30</update_rate>
        <visualize>true</visualize>
        <topic>model/spot/camera/frontleft_fisheye_image</topic>
        <pose>0 0.01 0 0 -0 0</pose>
        <camera>
          <horizontal_fov>1.78634</horizontal_fov>
          <image>
            <width>640</width>
            <height>480</height>
            <format>R8G8B8</format>
          </image>
          <clip>
            <near>0.1</near>
            <far>20</far>
          </clip>
          <noise>
            <type>gaussian</type>
            <mean>0</mean>
            <stddev>0.007</stddev>
          </noise>
          <lens>
            <intrinsics>
              <fx>257.487</fx>
              <fy>257.487</fy>
              <cx>319.5</cx>
              <cy>239.5</cy>
              <s>0</s>
            </intrinsics>
            <type>stereographic</type>
            <scale_to_hfov>1</scale_to_hfov>
          </lens>
        </camera>
      </sensor>
      <sensor name="frontleft_depth" type="depth_camera">
        <always_on>1</always_on>
        <update_rate>30</update_rate>
        <visualize>true</visualize>
        <topic>model/spot/camera/frontleft_depth</topic>
        <camera>
          <horizontal_fov>1.78634</horizontal_fov>
          <image>
            <width>424</width>
            <height>240</height>
            <format>R_FLOAT32</format>
          </image>
          <clip>
            <near>0.1</near>
            <far>4</far>
          </clip>
          <noise>
            <type>gaussian</type>
            <mean>0</mean>
            <stddev>0.007</stddev>
          </noise>
          <lens>
            <intrinsics>
              <fx>170.6</fx>
              <fy>170.6</fy>
              <cx>211.5</cx>
              <cy>119.5</cy>
              <s>0</s>
            </intrinsics>
            <type>stereographic</type>
            <scale_to_hfov>1</scale_to_hfov>
          </lens>
        </camera>
      </sensor>
    </link>
    <joint name="camera_frontleft_j" type="fixed">
      <child>camera_frontleft</child>
      <parent>base_link</parent>
      <axis>
        <dynamics>
          <spring_reference>0</spring_reference>
          <spring_stiffness>0</spring_stiffness>
        </dynamics>
        <xyz>0 0 1</xyz>
        <limit>
          <lower>-1e+16</lower>
          <upper>1e+16</upper>
        </limit>
      </axis>
      <physics>
        <ode>
          <limit>
            <cfm>0</cfm>
            <erp>0.2</erp>
          </limit>
        </ode>
      </physics>
    </joint>
    <link name="camera_frontright">
      <pose>0.415 -0.037 -0.01 -1.35556 0.353917 0.554196</pose>
      <inertial>
        <mass>1e-05</mass>
        <inertia>
          <ixx>0.001</ixx>
          <ixy>1e-06</ixy>
          <ixz>1e-06</ixz>
          <iyy>0.001</iyy>
          <iyz>1e-06</iyz>
          <izz>0.001</izz>
        </inertia>
      </inertial>
      <sensor name="frontright_fisheye_image" type="camera">
        <always_on>1</always_on>
        <update_rate>30</update_rate>
        <visualize>true</visualize>
        <topic>model/spot/camera/frontright_fisheye_image</topic>
        <pose>0 0.01 0 0 -0 0</pose>
        <camera>
          <horizontal_fov>1.78634</horizontal_fov>
          <image>
            <width>640</width>
            <height>480</height>
            <format>R8G8B8</format>
          </image>
          <clip>
            <near>0.1</near>
            <far>20</far>
          </clip>
          <noise>
            <type>gaussian</type>
            <mean>0</mean>
            <stddev>0.007</stddev>
          </noise>
          <lens>
            <intrinsics>
              <fx>257.487</fx>
              <fy>257.487</fy>
              <cx>319.5</cx>
              <cy>239.5</cy>
              <s>0</s>
            </intrinsics>
            <type>stereographic</type>
            <scale_to_hfov>1</scale_to_hfov>
          </lens>
        </camera>
      </sensor>
      <sensor name="frontright_depth" type="depth_camera">
        <always_on>1</always_on>
        <update_rate>30</update_rate>
        <visualize>true</visualize>
        <topic>model/spot/camera/frontright_depth</topic>
        <camera>
          <horizontal_fov>1.78634</horizontal_fov>
          <image>
            <width>424</width>
            <height>240</height>
            <format>R_FLOAT32</format>
          </image>
          <clip>
            <near>0.1</near>
            <far>4</far>
          </clip>
          <noise>
            <type>gaussian</type>
            <mean>0</mean>
            <stddev>0.007</stddev>
          </noise>
          <lens>
            <intrinsics>
              <fx>170.6</fx>
              <fy>170.6</fy>
              <cx>211.5</cx>
              <cy>119.5</cy>
              <s>0</s>
            </intrinsics>
            <type>stereographic</type>
            <scale_to_hfov>1</scale_to_hfov>
          </lens>
        </camera>
      </sensor>
    </link>
    <joint name="camera_frontright_j" type="fixed">
      <child>camera_frontright</child>
      <parent>base_link</parent>
      <axis>
        <dynamics>
          <spring_reference>0</spring_reference>
          <spring_stiffness>0</spring_stiffness>
        </dynamics>
        <xyz>0 0 1</xyz>
        <limit>
          <lower>-1e+16</lower>
          <upper>1e+16</upper>
        </limit>
      </axis>
      <physics>
        <ode>
          <limit>
            <cfm>0</cfm>
            <erp>0.2</erp>
          </limit>
        </ode>
      </physics>
    </joint>
    <link name="camera_left">
      <pose>-0.125 0.12 0.035 0 0.2 1.5707963267948966</pose>
      <inertial>
        <mass>1e-05</mass>
        <inertia>
          <ixx>0.001</ixx>
          <ixy>1e-06</ixy>
          <ixz>1e-06</ixz>
          <iyy>0.001</iyy>
          <iyz>1e-06</iyz>
          <izz>0.001</izz>
        </inertia>
      </inertial>
      <sensor name="left_fisheye_image" type="camera">
        <always_on>1</always_on>
        <update_rate>30</update_rate>
        <visualize>true</visualize>
        <topic>model/spot/camera/left_fisheye_image</topic>
        <pose>0 0.01 0 0 -0 0</pose>
        <camera>
          <horizontal_fov>1.78634</horizontal_fov>
          <image>
            <width>640</width>
            <height>480</height>
            <format>R8G8B8</format>
          </image>
          <clip>
            <near>0.1</near>
            <far>20</far>
          </clip>
          <noise>
            <type>gaussian</type>
            <mean>0</mean>
            <stddev>0.007</stddev>
          </noise>
          <lens>
            <intrinsics>
              <fx>257.487</fx>
              <fy>257.487</fy>
              <cx>319.5</cx>
              <cy>239.5</cy>
              <s>0</s>
            </intrinsics>
            <type>stereographic</type>
            <scale_to_hfov>1</scale_to_hfov>
          </lens>
        </camera>
      </sensor>
      <sensor name="left_depth" type="depth_camera">
        <always_on>1</always_on>
        <update_rate>30</update_rate>
        <visualize>true</visualize>
        <topic>model/spot/camera/left_depth</topic>
        <camera>
          <horizontal_fov>1.78634</horizontal_fov>
          <image>
            <width>424</width>
            <height>240</height>
            <format>R_FLOAT32</format>
          </image>
          <clip>
            <near>0.1</near>
            <far>4</far>
          </clip>
          <noise>
            <type>gaussian</type>
            <mean>0</mean>
            <stddev>0.007</stddev>
          </noise>
          <lens>
            <intrinsics>
              <fx>170.6</fx>
              <fy>170.6</fy>
              <cx>211.5</cx>
              <cy>119.5</cy>
              <s>0</s>
            </intrinsics>
            <type>stereographic</type>
            <scale_to_hfov>1</scale_to_hfov>
          </lens>
        </camera>
      </sensor>
    </link>
    <joint name="camera_left_j" type="fixed">
      <child>camera_left</child>
      <parent>base_link</parent>
      <axis>
        <dynamics>
          <spring_reference>0</spring_reference>
          <spring_stiffness>0</spring_stiffness>
        </dynamics>
        <xyz>0 0 1</xyz>
        <limit>
          <lower>-1e+16</lower>
          <upper>1e+16</upper>
        </limit>
      </axis>
      <physics>
        <ode>
          <limit>
            <cfm>0</cfm>
            <erp>0.2</erp>
          </limit>
        </ode>
      </physics>
    </joint>
    <link name="camera_right">
      <pose>-0.125 -0.12 0.035 -0 0.2 -1.5707963267948966</pose>
      <inertial>
        <mass>1e-05</mass>
        <inertia>
          <ixx>0.001</ixx>
          <ixy>1e-06</ixy>
          <ixz>1e-06</ixz>
          <iyy>0.001</iyy>
          <iyz>1e-06</iyz>
          <izz>0.001</izz>
        </inertia>
      </inertial>
      <sensor name="right_fisheye_image" type="camera">
        <always_on>1</always_on>
        <update_rate>30</update_rate>
        <visualize>true</visualize>
        <topic>model/spot/camera/right_fisheye_image</topic>
        <pose>0 0.01 0 0 -0 0</pose>
        <camera>
          <horizontal_fov>1.78634</horizontal_fov>
          <image>
            <width>640</width>
            <height>480</height>
            <format>R8G8B8</format>
          </image>
          <clip>
            <near>0.1</near>
            <far>20</far>
          </clip>
          <noise>
            <type>gaussian</type>
            <mean>0</mean>
            <stddev>0.007</stddev>
          </noise>
          <lens>
            <intrinsics>
              <fx>257.487</fx>
              <fy>257.487</fy>
              <cx>319.5</cx>
              <cy>239.5</cy>
              <s>0</s>
            </intrinsics>
            <type>stereographic</type>
            <scale_to_hfov>1</scale_to_hfov>
          </lens>
        </camera>
      </sensor>
      <sensor name="right_depth" type="depth_camera">
        <always_on>1</always_on>
        <update_rate>30</update_rate>
        <visualize>true</visualize>
        <topic>model/spot/camera/right_depth</topic>
        <camera>
          <horizontal_fov>1.78634</horizontal_fov>
          <image>
            <width>424</width>
            <height>240</height>
            <format>R_FLOAT32</format>
          </image>
          <clip>
            <near>0.1</near>
            <far>4</far>
          </clip>
          <noise>
            <type>gaussian</type>
            <mean>0</mean>
            <stddev>0.007</stddev>
          </noise>
          <lens>
            <intrinsics>
              <fx>170.6</fx>
              <fy>170.6</fy>
              <cx>211.5</cx>
              <cy>119.5</cy>
              <s>0</s>
            </intrinsics>
            <type>stereographic</type>
            <scale_to_hfov>1</scale_to_hfov>
          </lens>
        </camera>
      </sensor>
    </link>
    <joint name="camera_right_j" type="fixed">
      <child>camera_right</child>
      <parent>base_link</parent>
      <axis>
        <dynamics>
          <spring_reference>0</spring_reference>
          <spring_stiffness>0</spring_stiffness>
        </dynamics>
        <xyz>0 0 1</xyz>
        <limit>
          <lower>-1e+16</lower>
          <upper>1e+16</upper>
        </limit>
      </axis>
      <physics>
        <ode>
          <limit>
            <cfm>0</cfm>
            <erp>0.2</erp>
          </limit>
        </ode>
      </physics>
    </joint>
    <link name="front_left_hip">
      <pose>0.29785 0.055 0 0 -0 0</pose>
      <inertial>
        <mass>2</mass>
        <inertia>
          <ixx>0.0027</ixx>
          <ixy>0</ixy>
          <ixz>0</ixz>
          <iyy>0.00416667</iyy>
          <iyz>0</iyz>
          <izz>0.00416667</izz>
        </inertia>
      </inertial>
      <collision name="front_left_hip_collision">
        <geometry>
          <mesh>
            <uri>package://spot_description/models/spot/meshes/front_left_hip_collision.stl</uri>
          </mesh>
        </geometry>
      </collision>
      <visual name="front_left_hip_visual">
        <geometry>
          <mesh>
            <uri>package://spot_description/models/spot/meshes/front_left_hip.dae</uri>
          </mesh>
        </geometry>
      </visual>
    </link>

    <joint name="front_left_hip_x" type="revolute">
      <child>front_left_hip</child>
      <parent>base_link</parent>
      <axis>
        <xyz>1 0 0</xyz>
        <limit>
          <lower>-0.785398</lower>
          <upper>0.785398</upper>
          <effort>80</effort>
          <velocity>15</velocity>
        </limit>
        <dynamics>
          <spring_reference>0</spring_reference>
          <spring_stiffness>0</spring_stiffness>
        </dynamics>
      </axis>
    </joint>
    <link name="front_left_upper_leg">
      <pose>0.29785 0.165945 0 0 -0 0</pose>
      <inertial>
        <pose>0 0 -0.14 0 -0 0</pose>
        <mass>1</mass>
        <inertia>
          <ixx>0.0155334</ixx>
          <ixy>0</ixy>
          <ixz>0</ixz>
          <iyy>0.0155334</iyy>
          <iyz>0</iyz>
          <izz>0.000962667</izz>
        </inertia>
      </inertial>
      <collision name="front_left_upper_leg_collision">
        <geometry>
          <mesh>
            <uri>package://spot_description/models/spot/meshes/front_left_upper_leg_collision.stl</uri>
          </mesh>
        </geometry>
      </collision>
      <visual name="front_left_upper_leg_visual">
        <geometry>
          <mesh>
            <uri>package://spot_description/models/spot/meshes/front_left_upper_leg.dae</uri>
          </mesh>
        </geometry>
      </visual>
    </link>
    <joint name="front_left_hip_y" type="revolute">
      <child>front_left_upper_leg</child>
      <parent>front_left_hip</parent>
      <axis>
        <xyz>0 1 0</xyz>
        <limit>
          <lower>-0.898845</lower>
          <upper>2.29511</upper>
          <effort>80</effort>
          <velocity>15</velocity>
        </limit>
        <dynamics>
          <spring_reference>0</spring_reference>
          <spring_stiffness>0</spring_stiffness>
        </dynamics>
      </axis>
    </joint>
    <link name="front_left_lower_leg">
      <pose>0.32285 0.165945 -0.3205 0 -0 0</pose>
      <inertial>
        <pose>0 0 -0.16 0 -0 0</pose>
        <mass>0.5</mass>
        <inertia>
          <ixx>0.00743438Source Control</ixx>
          <ixy>0</ixy>
          <ixz>0</ixz>
          <iyy>0.00740104</iyy>
          <iyz>0</iyz>
          <izz>0.000135417</izz>
        </inertia>
      </inertial>
      <collision name="front_left_lower_leg_collision">
        <geometry>
          <mesh>
            <scale>0.82 0.97 0.98</scale>
            <uri>package://spot_description/models/spot/meshes/front_left_lower_leg_collision.stl</uri>
          </mesh>
        </geometry>
        <surface>
          <contact>
            <ode>
              <kp>1e+07</kp>
              <kd>100</kd>
            </ode>
          </contact>
          <friction>
            <ode>
              <mu>0.8</mu>
              <mu2>0.8</mu2>
            </ode>
          </friction>
        </surface>
      </collision>
      <collision name="front_left_lower_leg_collision_1">
        <pose>0 0 -0.333 0 -0 0</pose>
        <geometry>
          <sphere>
            <radius>0.04</radius>
          </sphere>
        </geometry>
        <surface>
          <contact>
            <ode>
              <kp>1e+07</kp>
              <kd>100</kd>
            </ode>
          </contact>
          <friction>
            <ode>
              <mu>0.8</mu>
              <mu2>0.8</mu2>
            </ode>
          </friction>
        </surface>
      </collision>
      <visual name="front_left_lower_leg_visual">
        <geometry>
          <mesh>
            <uri>package://spot_description/models/spot/meshes/front_left_lower_leg.dae</uri>
          </mesh>
        </geometry>
        <material>
        </material>
      </visual>
      <sensor name="contact" type="contact">
        <contact>
          <collision>front_left_lower_leg_collision</collision>
          <collision>front_left_lower_leg_collision_1</collision>
          <topic>__default_topic__</topic>
        </contact>
      </sensor>
    </link>
    <joint name="front_left_knee" type="revolute">
      <child>front_left_lower_leg</child>
      <parent>front_left_upper_leg</parent>
      <axis>
        <xyz>0 1 0</xyz>
        <limit>
          <lower>-2.7929</lower>
          <upper>-0.254801</upper>
          <effort>80</effort>
          <velocity>15</velocity>
        </limit>
        <dynamics>
          <spring_reference>0</spring_reference>
          <spring_stiffness>0</spring_stiffness>
        </dynamics>
      </axis>
    </joint>
    <link name="front_left_ee">
      <pose>0.32285 0.165945 -0.6905 0 -0 0</pose>
      <inertial>
        <mass>1e-05</mass>
        <inertia>
          <ixx>0.001</ixx>
          <ixy>1e-06</ixy>
          <ixz>1e-06</ixz>
          <iyy>0.001</iyy>
          <iyz>1e-06</iyz>
          <izz>0.001</izz>
        </inertia>
      </inertial>
    </link>
    <joint name="front_left_foot" type="fixed">
  
      <child>front_left_ee</child>
      <parent>front_left_lower_leg</parent>
      <axis>
        <dynamics>
          <spring_reference>0</spring_reference>
          <spring_stiffness>0</spring_stiffness>
        </dynamics>
        <xyz>0 0 1</xyz>
        <limit>
          <lower>-1e+16</lower>
          <upper>1e+16</upper>
        </limit>
      </axis>
      <physics>
        <ode>
          <limit>
            <cfm>0</cfm>
            <erp>0.2</erp>
          </limit>
        </ode>
      </physics>
    </joint>
    <link name="front_right_hip">
      <pose>0.29785 -0.055 0 0 -0 0</pose>
      <inertial>
        <mass>2</mass>
        <inertia>
          <ixx>0.0027</ixx>
          <ixy>0</ixy>
          <ixz>0</ixz>
          <iyy>0.00416667</iyy>
          <iyz>0</iyz>
          <izz>0.00416667</izz>
        </inertia>
      </inertial>
      <collision name="front_right_hip_collision">
        <geometry>
          <mesh>
            <uri>package://spot_description/models/spot/meshes/front_right_hip_collision.stl</uri>
          </mesh>
        </geometry>
      </collision>
      <visual name="front_right_hip_visual">
        <geometry>
          <mesh>
            <uri>package://spot_description/models/spot/meshes/front_right_hip.dae</uri>
          </mesh>
        </geometry>
      </visual>
    </link>
    <joint name="front_right_hip_x" type="revolute">
      <child>front_right_hip</child>
      <parent>base_link</parent>
      <axis>
        <xyz>1 0 0</xyz>
        <limit>
          <lower>-0.785398</lower>
          <upper>0.785398</upper>
          <effort>80</effort>
          <velocity>15</velocity>
        </limit>
        <dynamics>
          <spring_reference>0</spring_reference>
          <spring_stiffness>0</spring_stiffness>
        </dynamics>
      </axis>
    </joint>
    <link name="front_right_upper_leg">
      <pose>0.29785 -0.165945 0 0 -0 0</pose>
      <inertial>
        <pose>0 0 -0.14 0 -0 0</pose>
        <mass>1</mass>
        <inertia>
          <ixx>0.0155334</ixx>
          <ixy>0</ixy>
          <ixz>0</ixz>
          <iyy>0.0155334</iyy>
          <iyz>0</iyz>
          <izz>0.000962667</izz>
        </inertia>
      </inertial>
      <collision name="front_right_upper_leg_collision">
        <geometry>
          <mesh>
            <uri>package://spot_description/models/spot/meshes/front_right_upper_leg_collision.stl</uri>
          </mesh>
        </geometry>
      </collision>
      <visual name="front_right_upper_leg_visual">
        <geometry>
          <mesh>
            <uri>package://spot_description/models/spot/meshes/front_right_upper_leg.dae</uri>
          </mesh>
        </geometry>
      </visual>
    </link>
    <joint name="front_right_hip_y" type="revolute">
      <child>front_right_upper_leg</child>
      <parent>front_right_hip</parent>
      <axis>
        <xyz>0 1 0</xyz>
        <limit>
          <lower>-0.898845</lower>
          <upper>2.29511</upper>
          <effort>80</effort>
          <velocity>15</velocity>
        </limit>
        <dynamics>
          <spring_reference>0</spring_reference>
          <spring_stiffness>0</spring_stiffness>
        </dynamics>
      </axis>
    </joint>
    <link name="front_right_lower_leg">
      <pose>0.32285 -0.165945 -0.3205 0 -0 0</pose>
      <inertial>
        <pose>0 0 -0.16 0 -0 0</pose>
        <mass>0.5</mass>
        <inertia>
          <ixx>0.00743438</ixx>
          <ixy>0</ixy>
          <ixz>0</ixz>
          <iyy>0.00740104</iyy>
          <iyz>0</iyz>
          <izz>0.000135417</izz>
        </inertia>
      </inertial>
      <collision name="front_right_lower_leg_collision">
        <geometry>
          <mesh>
            <scale>0.82 0.97 0.98</scale>
            <uri>package://spot_description/models/spot/meshes/front_right_lower_leg_collision.stl</uri>
          </mesh>
        </geometry>
        <surface>
          <contact>
            <ode>
              <kp>1e+07</kp>
              <kd>100</kd>
            </ode>
          </contact>
          <friction>
            <ode>
              <mu>0.8</mu>
              <mu2>0.8</mu2>
            </ode>
          </friction>
        </surface>
      </collision>
      <collision name="front_right_lower_leg_collision_1">
        <pose>0 0 -0.333 0 -0 0</pose>
        <geometry>
          <sphere>
            <radius>0.04</radius>
          </sphere>
        </geometry>
        <surface>
          <contact>
            <ode>
              <kp>1e+07</kp>
              <kd>100</kd>
            </ode>
          </contact>
          <friction>
            <ode>
              <mu>0.8</mu>
              <mu2>0.8</mu2>
            </ode>
          </friction>
        </surface>
      </collision>
      <visual name="front_right_lower_leg_visual">
        <geometry>
          <mesh>
            <uri>package://spot_description/models/spot/meshes/front_right_lower_leg.dae</uri>
          </mesh>
        </geometry>
        <material>
        </material>
      </visual>
      <sensor name="contact" type="contact">
        <contact>
          <collision>front_right_lower_leg_collision</collision>
          <collision>front_right_lower_leg_collision_1</collision>
          <topic>__default_topic__</topic>
        </contact>
      </sensor>
    </link>
    <joint name="front_right_knee" type="revolute">
      <child>front_right_lower_leg</child>
      <parent>front_right_upper_leg</parent>
      <axis>
        <xyz>0 1 0</xyz>
        <limit>
          <lower>-2.7929</lower>
          <upper>-0.254801</upper>
          <effort>80</effort>
          <velocity>15</velocity>
        </limit>
        <dynamics>
          <spring_reference>0</spring_reference>
          <spring_stiffness>0</spring_stiffness>
        </dynamics>
      </axis>
    </joint>
    <link name="front_right_ee">
      <pose>0.32285 -0.165945 -0.6905 0 -0 0</pose>
      <inertial>
        <mass>1e-05</mass>
        <inertia>
          <ixx>0.001</ixx>
          <ixy>1e-06</ixy>
          <ixz>1e-06</ixz>
          <iyy>0.001</iyy>
          <iyz>1e-06</iyz>
          <izz>0.001</izz>
        </inertia>
      </inertial>
    </link>
    <joint name="front_right_foot" type="fixed">
      <child>front_right_ee</child>
      <parent>front_right_lower_leg</parent>
      <axis>
        <dynamics>
          <spring_reference>0</spring_reference>
          <spring_stiffness>0</spring_stiffness>
        </dynamics>
        <xyz>0 0 1</xyz>
        <limit>
          <lower>-1e+16</lower>
          <upper>1e+16</upper>
        </limit>
      </axis>
      <physics>
        <ode>
          <limit>
            <cfm>0</cfm>
            <erp>0.2</erp>
          </limit>
        </ode>
      </physics>
    </joint>
    <link name="imu">
      <sensor name="imu" type="imu">
        <always_on>1</always_on>
        <update_rate>100</update_rate>
        <topic>model/spot/imu</topic>
        <imu>
          <enable_orientation>0</enable_orientation>
          <angular_velocity>
            <x>
              <noise type="gaussian">
                <mean>0</mean>
                <stddev>0.009</stddev>
                <bias_mean>0.00075</bias_mean>
                <bias_stddev>0.005</bias_stddev>
                <dynamic_bias_stddev>2e-05</dynamic_bias_stddev>
                <dynamic_bias_correlation_time>400</dynamic_bias_correlation_time>
                <precision>0.00025</precision>
              </noise>
            </x>
            <y>
              <noise type="gaussian">
                <mean>0</mean>
                <stddev>0.009</stddev>
                <bias_mean>0.00075</bias_mean>
                <bias_stddev>0.005</bias_stddev>
                <dynamic_bias_stddev>2e-05</dynamic_bias_stddev>
                <dynamic_bias_correlation_time>400</dynamic_bias_correlation_time>
                <precision>0.00025</precision>
              </noise>
            </y>
            <z>
              <noise type="gaussian">
                <mean>0</mean>
                <stddev>0.009</stddev>
                <bias_mean>0.00075</bias_mean>
                <bias_stddev>0.005</bias_stddev>
                <dynamic_bias_stddev>2e-05</dynamic_bias_stddev>
                <dynamic_bias_correlation_time>400</dynamic_bias_correlation_time>
                <precision>0.00025</precision>
              </noise>
            </z>
          </angular_velocity>
          <linear_acceleration>
            <x>
              <noise type="gaussian">
                <mean>0</mean>
                <stddev>0.021</stddev>
                <bias_mean>0.05</bias_mean>
                <bias_stddev>0.0075</bias_stddev>
                <dynamic_bias_stddev>0.000375</dynamic_bias_stddev>
                <dynamic_bias_correlation_time>175</dynamic_bias_correlation_time>
                <precision>0.005</precision>
              </noise>
            </x>
            <y>
              <noise type="gaussian">
                <mean>0</mean>
                <stddev>0.021</stddev>
                <bias_mean>0.05</bias_mean>
                <bias_stddev>0.0075</bias_stddev>
                <dynamic_bias_stddev>0.000375</dynamic_bias_stddev>
                <dynamic_bias_correlation_time>175</dynamic_bias_correlation_time>
                <precision>0.005</precision>
              </noise>
            </y>
            <z>
              <noise type="gaussian">
                <mean>0</mean>
                <stddev>0.021</stddev>
                <bias_mean>0.05</bias_mean>
                <bias_stddev>0.0075</bias_stddev>
                <dynamic_bias_stddev>0.000375</dynamic_bias_stddev>
                <dynamic_bias_correlation_time>175</dynamic_bias_correlation_time>
                <precision>0.005</precision>
              </noise>
            </z>
          </linear_acceleration>
        </imu>
      </sensor>
    </link>
    <joint name="imu_j" type="fixed">
      <child>imu</child>
      <parent>base_link</parent>
      <axis>
        <dynamics>
          <spring_reference>0</spring_reference>
          <spring_stiffness>0</spring_stiffness>
        </dynamics>
        <xyz>0 0 1</xyz>
        <limit>
          <lower>-1e+16</lower>
          <upper>1e+16</upper>
        </limit>
      </axis>
      <physics>
        <ode>
          <limit>
            <cfm>0</cfm>
            <erp>0.2</erp>
          </limit>
        </ode>
      </physics>
    </joint>
    <link name="rear_left_hip">
      <pose>-0.29785 0.055 0 0 -0 0</pose>
      <inertial>
        <mass>2</mass>
        <inertia>
          <ixx>0.0027</ixx>
          <ixy>0</ixy>
          <ixz>0</ixz>
          <iyy>0.00416667</iyy>
          <iyz>0</iyz>
          <izz>0.00416667</izz>
        </inertia>
      </inertial>
      <collision name="rear_left_hip_collision">
        <geometry>
          <mesh>
            <uri>package://spot_description/models/spot/meshes/rear_left_hip_collision.stl</uri>
          </mesh>
        </geometry>
      </collision>
      <visual name="rear_left_hip_visual">
        <geometry>
          <mesh>
            <uri>package://spot_description/models/spot/meshes/rear_left_hip.dae</uri>
          </mesh>
        </geometry>
      </visual>
    </link>
    <joint name="rear_left_hip_x" type="revolute">
      <child>rear_left_hip</child>
      <parent>base_link</parent>
      <axis>
        <xyz>1 0 0</xyz>
        <limit>
          <lower>-0.785398</lower>
          <upper>0.785398</upper>
          <effort>80</effort>
          <velocity>15</velocity>
        </limit>
        <dynamics>
          <spring_reference>0</spring_reference>
          <spring_stiffness>0</spring_stiffness>
        </dynamics>
      </axis>
    </joint>
    <link name="rear_left_upper_leg">
      <pose>-0.29785 0.165945 0 0 -0 0</pose>
      <inertial>
        <pose>0 0 -0.14 0 -0 0</pose>
        <mass>1</mass>
        <inertia>
          <ixx>0.0155334</ixx>
          <ixy>0</ixy>
          <ixz>0</ixz>
          <iyy>0.0155334</iyy>
          <iyz>0</iyz>
          <izz>0.000962667</izz>
        </inertia>
      </inertial>
      <collision name="rear_left_upper_leg_collision">
        <geometry>
          <mesh>
            <uri>package://spot_description/models/spot/meshes/rear_left_upper_leg_collision.stl</uri>
          </mesh>
        </geometry>
      </collision>
      <visual name="rear_left_upper_leg_visual">
        <geometry>
          <mesh>
            <uri>package://spot_description/models/spot/meshes/rear_left_upper_leg.dae</uri>
          </mesh>
        </geometry>
      </visual>
    </link>
    <joint name="rear_left_hip_y" type="revolute">
      <child>rear_left_upper_leg</child>
      <parent>rear_left_hip</parent>
      <axis>
        <xyz>0 1 0</xyz>
        <limit>
          <lower>-0.898845</lower>
          <upper>2.29511</upper>
          <effort>80</effort>
          <velocity>15</velocity>
        </limit>
        <dynamics>
          <spring_reference>0</spring_reference>
          <spring_stiffness>0</spring_stiffness>
        </dynamics>
      </axis>
    </joint>
    <link name="rear_left_lower_leg">
      <pose>-0.27285 0.165945 -0.3205 0 -0 0</pose>
      <inertial>
        <pose>0 0 -0.16 0 -0 0</pose>
        <mass>0.5</mass>
        <inertia>
          <ixx>0.00743438</ixx>
          <ixy>0</ixy>
          <ixz>0</ixz>
          <iyy>0.00740104</iyy>
          <iyz>0</iyz>
          <izz>0.000135417</izz>
        </inertia>
      </inertial>
      <collision name="rear_left_lower_leg_collision">
        <geometry>
          <mesh>
            <scale>0.82 0.97 0.98</scale>
            <uri>package://spot_description/models/spot/meshes/rear_left_lower_leg_collision.stl</uri>
          </mesh>
        </geometry>
        <surface>
          <contact>
            <ode>
              <kp>1e+07</kp>
              <kd>100</kd>
            </ode>
          </contact>
          <friction>
            <ode>
              <mu>0.8</mu>
              <mu2>0.8</mu2>
            </ode>
          </friction>
        </surface>
      </collision>
      <collision name="rear_left_lower_leg_collision_1">
        <pose>0 0 -0.333 0 -0 0</pose>
        <geometry>
          <sphere>
            <radius>0.04</radius>
          </sphere>
        </geometry>
        <surface>
          <contact>
            <ode>
              <kp>1e+07</kp>
              <kd>100</kd>
            </ode>
          </contact>
          <friction>
            <ode>
              <mu>0.8</mu>
              <mu2>0.8</mu2>
            </ode>
          </friction>
        </surface>
      </collision>
      <visual name="rear_left_lower_leg_visual">
        <geometry>
          <mesh>
            <uri>package://spot_description/models/spot/meshes/rear_left_lower_leg.dae</uri>
          </mesh>
        </geometry>
        <material>
        </material>
      </visual>
      <sensor name="contact" type="contact">
        <contact>
          <collision>rear_left_lower_leg_collision</collision>
          <collision>rear_left_lower_leg_collision_1</collision>
          <topic>__default_topic__</topic>
        </contact>
      </sensor>
    </link>
    <joint name="rear_left_knee" type="revolute">
      <child>rear_left_lower_leg</child>
      <parent>rear_left_upper_leg</parent>
      <axis>
        <xyz>0 1 0</xyz>
        <limit>
          <lower>-2.7929</lower>
          <upper>-0.254801</upper>
          <effort>80</effort>
          <velocity>15</velocity>
        </limit>
        <dynamics>
          <spring_reference>0</spring_reference>
          <spring_stiffness>0</spring_stiffness>
        </dynamics>
      </axis>
    </joint>
    <link name="rear_left_ee">
      <pose>-0.27285 0.165945 -0.6905 0 -0 0</pose>
      <inertial>
        <mass>1e-05</mass>
        <inertia>
          <ixx>0.001</ixx>
          <ixy>1e-06</ixy>
          <ixz>1e-06</ixz>
          <iyy>0.001</iyy>
          <iyz>1e-06</iyz>
          <izz>0.001</izz>
        </inertia>
      </inertial>
    </link>
    <joint name="rear_left_foot" type="fixed">
      <child>rear_left_ee</child>
      <parent>rear_left_lower_leg</parent>
      <axis>
        <dynamics>
          <spring_reference>0</spring_reference>
          <spring_stiffness>0</spring_stiffness>
        </dynamics>
        <xyz>0 0 1</xyz>
        <limit>
          <lower>-1e+16</lower>
          <upper>1e+16</upper>
        </limit>
      </axis>
      <physics>
        <ode>
          <limit>
            <cfm>0</cfm>
            <erp>0.2</erp>
          </limit>
        </ode>
      </physics>
    </joint>
    <link name="rear_right_hip">
      <pose>-0.29785 -0.055 0 0 -0 0</pose>
      <inertial>
        <mass>2</mass>
        <inertia>
          <ixx>0.0027</ixx>
          <ixy>0</ixy>
          <ixz>0</ixz>
          <iyy>0.00416667</iyy>
          <iyz>0</iyz>
          <izz>0.00416667</izz>
        </inertia>
      </inertial>
      <collision name="rear_right_hip_collision">
        <geometry>
          <mesh>
            <uri>package://spot_description/models/spot/meshes/rear_right_hip_collision.stl</uri>
          </mesh>
        </geometry>
      </collision>
      <visual name="rear_right_hip_visual">
        <geometry>
          <mesh>
            <uri>package://spot_description/models/spot/meshes/rear_right_hip.dae</uri>
          </mesh>
        </geometry>
      </visual>
    </link>
    <joint name="rear_right_hip_x" type="revolute">
      <child>rear_right_hip</child>
      <parent>base_link</parent>
      <axis>
        <xyz>1 0 0</xyz>
        <limit>
          <lower>-0.785398</lower>
          <upper>0.785398</upper>
          <effort>80</effort>
          <velocity>15</velocity>
        </limit>
        <dynamics>
          <spring_reference>0</spring_reference>
          <spring_stiffness>0</spring_stiffness>
        </dynamics>
      </axis>
    </joint>
    <link name="rear_right_upper_leg">
      <pose>-0.29785 -0.165945 0 0 -0 0</pose>
      <inertial>
        <pose>0 0 -0.14 0 -0 0</pose>
        <mass>1</mass>
        <inertia>
          <ixx>0.0155334</ixx>
          <ixy>0</ixy>
          <ixz>0</ixz>
          <iyy>0.0155334</iyy>
          <iyz>0</iyz>
          <izz>0.000962667</izz>
        </inertia>
      </inertial>
      <collision name="rear_right_upper_leg_collision">
        <geometry>
          <mesh>
            <uri>package://spot_description/models/spot/meshes/rear_right_upper_leg_collision.stl</uri>
          </mesh>
        </geometry>
      </collision>
      <visual name="rear_right_upper_leg_visual">
        <geometry>
          <mesh>
            <uri>package://spot_description/models/spot/meshes/rear_right_upper_leg.dae</uri>
          </mesh>
        </geometry>
      </visual>
    </link>
    <joint name="rear_right_hip_y" type="revolute">
      <child>rear_right_upper_leg</child>
      <parent>rear_right_hip</parent>
      <axis>
        <xyz>0 1 0</xyz>
        <limit>
          <lower>-0.898845</lower>
          <upper>2.29511</upper>
          <effort>80</effort>
          <velocity>15</velocity>
        </limit>
        <dynamics>
          <spring_reference>0</spring_reference>
          <spring_stiffness>0</spring_stiffness>
        </dynamics>
      </axis>
    </joint>
    <link name="rear_right_lower_leg">
      <pose>-0.27285 -0.165945 -0.3205 0 -0 0</pose>
      <inertial>
        <pose>0 0 -0.16 0 -0 0</pose>
        <mass>0.5</mass>
        <inertia>
          <ixx>0.00743438</ixx>
          <ixy>0</ixy>
          <ixz>0</ixz>
          <iyy>0.00740104</iyy>
          <iyz>0</iyz>
          <izz>0.000135417</izz>
        </inertia>
      </inertial>
      <collision name="rear_right_lower_leg_collision">
        <geometry>
          <mesh>
            <scale>0.82 0.97 0.98</scale>
            <uri>package://spot_description/models/spot/meshes/rear_right_lower_leg_collision.stl</uri>
          </mesh>
        </geometry>
        <surface>
          <contact>
            <ode>
              <kp>1e+07</kp>
              <kd>100</kd>
            </ode>
          </contact>
          <friction>
            <ode>
              <mu>0.8</mu>
              <mu2>0.8</mu2>
            </ode>
          </friction>
        </surface>
      </collision>
      <collision name="rear_right_lower_leg_collision_1">
        <pose>0 0 -0.333 0 -0 0</pose>
        <geometry>
          <sphere>
            <radius>0.04</radius>
          </sphere>
        </geometry>
        <surface>
          <contact>
            <ode>
              <kp>1e+07</kp>
              <kd>100</kd>
            </ode>
          </contact>
          <friction>
            <ode>
              <mu>0.8</mu>
              <mu2>0.8</mu2>
            </ode>
          </friction>
        </surface>
      </collision>
      <visual name="rear_right_lower_leg_visual">
        <geometry>
          <mesh>
            <uri>package://spot_description/models/spot/meshes/rear_right_lower_leg.dae</uri>
          </mesh>
        </geometry>
        <material>
        </material>
      </visual>
      <sensor name="contact" type="contact">
        <contact>
          <collision>rear_right_lower_leg_collision</collision>
          <collision>rear_right_lower_leg_collision_1</collision>
          <topic>__default_topic__</topic>
        </contact>
      </sensor>
    </link>
    <joint name="rear_right_knee" type="revolute">
      <child>rear_right_lower_leg</child>
      <parent>rear_right_upper_leg</parent>
      <axis>
        <xyz>0 1 0</xyz>
        <limit>
          <lower>-2.7929</lower>
          <upper>-0.254801</upper>
          <effort>80</effort>
          <velocity>15</velocity>
        </limit>
        <dynamics>
          <spring_reference>0</spring_reference>
          <spring_stiffness>0</spring_stiffness>
        </dynamics>
      </axis>
    </joint>
    <link name="rear_right_ee">
      <pose>-0.27285 -0.165945 -0.6905 0 -0 0</pose>
      <inertial>
        <mass>1e-05</mass>
        <inertia>
          <ixx>0.001</ixx>
          <ixy>1e-06</ixy>
          <ixz>1e-06</ixz>
          <iyy>0.001</iyy>
          <iyz>1e-06</iyz>
          <izz>0.001</izz>
        </inertia>
      </inertial>
    </link>
    <joint name="rear_right_foot" type="fixed">
      <child>rear_right_ee</child>
      <parent>rear_right_lower_leg</parent>
      <axis>
        <dynamics>
          <spring_reference>0</spring_reference>
          <spring_stiffness>0</spring_stiffness>
        </dynamics>
        <xyz>0 0 1</xyz>
        <limit>
          <lower>-1e+16</lower>
          <upper>1e+16</upper>
        </limit>
      </axis>
      <physics>
        <ode>
          <limit>
            <cfm>0</cfm>
            <erp>0.2</erp>
          </limit>
        </ode>
      </physics>
    </joint>

    <plugin
      filename="ignition-gazebo-imu-system"
      name="ignition::gazebo::systems::Imu">
    </plugin>

    <plugin
      filename="ignition-gazebo-joint-state-publisher-system"
      name="ignition::gazebo::systems::JointStatePublisher">
      <topic>model/spot/joint_state</topic>
      <update_rate>200</update_rate>
    </plugin>

    <plugin
      filename="ignition-gazebo-odometry-publisher-system"
      name="ignition::gazebo::systems::OdometryPublisher">
      <odom_publish_frequency>10</odom_publish_frequency>
      <odom_topic>/model/spot/odometry</odom_topic>
      <odom_frame>/odom_spot</odom_frame>
      <robot_base_frame>base_link</robot_base_frame>
      <dimensions>3</dimensions>
    </plugin>

    <plugin
      filename="ignition-gazebo-joint-trajectory-controller-system"
      name="ignition::gazebo::systems::JointTrajectoryController">
      <topic>model/spot/joint_trajectory</topic>

      <joint_name>front_left_hip_x</joint_name>
      <position_p_gain>500</position_p_gain>
      <position_i_gain>1</position_i_gain>
      <position_d_gain>20</position_d_gain>

      <joint_name>front_left_hip_y</joint_name>
      <position_p_gain>500</position_p_gain>
      <position_i_gain>1</position_i_gain>
      <position_d_gain>20</position_d_gain>

      <joint_name>front_left_knee</joint_name>
      <position_p_gain>500</position_p_gain>
      <position_i_gain>1</position_i_gain>
      <position_d_gain>20</position_d_gain>

      <joint_name>front_right_hip_x</joint_name>
      <position_p_gain>500</position_p_gain>
      <position_i_gain>1</position_i_gain>
      <position_d_gain>20</position_d_gain>

      <joint_name>front_right_hip_y</joint_name>
      <position_p_gain>500</position_p_gain>
      <position_i_gain>1</position_i_gain>
      <position_d_gain>20</position_d_gain>

      <joint_name>front_right_knee</joint_name>
      <position_p_gain>500</position_p_gain>
      <position_i_gain>1</position_i_gain>
      <position_d_gain>20</position_d_gain>

      <joint_name>rear_left_hip_x</joint_name>
      <position_p_gain>500</position_p_gain>
      <position_i_gain>1</position_i_gain>
      <position_d_gain>20</position_d_gain>

      <joint_name>rear_left_hip_y</joint_name>
      <position_p_gain>500</position_p_gain>
      <position_i_gain>1</position_i_gain>
      <position_d_gain>20</position_d_gain>

      <joint_name>rear_left_knee</joint_name>
      <position_p_gain>500</position_p_gain>
      <position_i_gain>1</position_i_gain>
      <position_d_gain>20</position_d_gain>

      <joint_name>rear_right_hip_x</joint_name>
      <position_p_gain>500</position_p_gain>
      <position_i_gain>1</position_i_gain>
      <position_d_gain>20</position_d_gain>

      <joint_name>rear_right_hip_y</joint_name>
      <position_p_gain>500</position_p_gain>
      <position_i_gain>1</position_i_gain>
      <position_d_gain>20</position_d_gain>

      <joint_name>rear_right_knee</joint_name>
      <position_p_gain>500</position_p_gain>
      <position_i_gain>1</position_i_gain>
      <position_d_gain>20</position_d_gain>
    </plugin>

  </model>
</sdf>
