<?xml version="1.0" ?>
<robot name="spot">
  <link name="base_link">
    <visual>
      <geometry>
        <mesh filename="package://spot_description/meshes/body.dae"/>
      </geometry>
    </visual>
    <collision>
      <geometry>
        <mesh filename="package://spot_description/meshes/body_collision.stl"/>
      </geometry>
    </collision>
    <inertial>
      <mass value="16.0"/>
      <inertia ixx="0.09733333333333333" ixy="0.0" ixz="0.0" iyy="1.0246666666666666" iyz="0.0" izz="1.0449333333333333"/>
    </inertial>
  </link>
  <link name="body"/>
  <joint name="base_link_joint" type="fixed">
    <origin rpy="0 0 0" xyz="0 0 0"/>
    <parent link="base_link"/>
    <child link="body"/>
  </joint>
  <link name="front_rail"/>
  <joint name="front_rail_joint" type="fixed">
    <origin rpy="0 0 0" xyz="0.223 0 0.0805"/>
    <parent link="base_link"/>
    <child link="front_rail"/>
  </joint>
  <link name="rear_rail"/>
  <joint name="rear_rail_joint" type="fixed">
    <origin rpy="0 0 0" xyz="-0.223 0 0.0805"/>
    <parent link="base_link"/>
    <child link="rear_rail"/>
  </joint>
  <link name="front_left_hip">
    <visual>
      <geometry>
        <mesh filename="package://spot_description/meshes/front_left_hip.dae"/>
      </geometry>
    </visual>
    <collision>
      <geometry>
        <mesh filename="package://spot_description/meshes/front_left_hip_collision.stl"/>
      </geometry>
    </collision>
    <inertial>
      <mass value="2.0"/>
      <inertia ixx="0.0026999999999999997" ixy="0.0" ixz="0.0" iyy="0.004166666666666667" iyz="0.0" izz="0.004166666666666667"/>
    </inertial>
  </link>
  <joint name="front_left_hip_x" type="revolute">
    <origin rpy="0 0 0" xyz="0.29785 0.055 0"/>
    <axis xyz="1 0 0"/>
    <parent link="body"/>
    <child link="front_left_hip"/>
    <limit effort="100" lower="-0.78539816339744827899" upper="0.78539816339744827899" velocity="1000.00"/>
  </joint>
  <link name="front_left_upper_leg">
    <visual>
      <geometry>
        <mesh filename="package://spot_description/meshes/front_left_upper_leg.dae"/>
      </geometry>
    </visual>
    <collision>
      <geometry>
        <mesh filename="package://spot_description/meshes/front_left_upper_leg_collision.stl"/>
      </geometry>
    </collision>
    <inertial>
      <origin rpy="0 0 0" xyz="0 0 -0.14"/>
      <mass value="1.0"/>
      <inertia ixx="0.015533416666666664" ixy="0.0" ixz="0.0" iyy="0.015533416666666664" iyz="0.0" izz="0.0009626666666666666"/>
    </inertial>
  </link>
  <joint name="front_left_hip_y" type="revolute">
    <origin rpy="0 0 0" xyz="0 0.110945 0"/>
    <axis xyz="0 1 0"/>
    <parent link="front_left_hip"/>
    <child link="front_left_upper_leg"/>
    <limit effort="100" lower="-0.89884456477707963539" upper="2.2951079663725435509" velocity="1000.00"/>
  </joint>
  <link name="front_left_lower_leg">
    <visual>
      <geometry>
        <mesh filename="package://spot_description/meshes/front_left_lower_leg.dae"/>
      </geometry>
    </visual>
    <collision>
      <geometry>
        <mesh filename="package://spot_description/meshes/front_left_lower_leg_collision.stl" scale="-1.82 0.97 0.98"/>
      </geometry>
    </collision>
    <inertial>
      <origin rpy="0 0 0" xyz="0 0 -0.16"/>
      <mass value="0.5"/>
      <inertia ixx="0.007434374999999998" ixy="0.0" ixz="0.0" iyy="0.007401041666666665" iyz="0.0" izz="0.00013541666666666666"/>
    </inertial>
  </link>
  <joint name="front_left_knee" type="revolute">
    <origin rpy="0 0 0" xyz="0.025 0 -0.3205"/>
    <axis xyz="0 1 0"/>
    <parent link="front_left_upper_leg"/>
    <child link="front_left_lower_leg"/>
    <limit effort="100" lower="-2.7929" upper="-0.254801" velocity="1000.00"/>
  </joint>
  <link name="front_left_ee"/>
  <joint name="front_left_foot" type="fixed">
    <parent link="front_left_lower_leg"/>
    <child link="front_left_ee"/>
    <origin rpy="0 0 0" xyz="0 0 -0.37"/>
  </joint>
  <link name="front_right_hip">
    <visual>
      <geometry>
        <mesh filename="package://spot_description/meshes/front_right_hip.dae"/>
      </geometry>
    </visual>
    <collision>
      <geometry>
        <mesh filename="package://spot_description/meshes/front_right_hip_collision.stl"/>
      </geometry>
    </collision>
    <inertial>
      <mass value="2.0"/>
      <inertia ixx="0.0026999999999999997" ixy="0.0" ixz="0.0" iyy="0.004166666666666667" iyz="0.0" izz="0.004166666666666667"/>
    </inertial>
  </link>
  <joint name="front_right_hip_x" type="revolute">
    <origin rpy="0 0 0" xyz="0.29785 -0.055 0"/>
    <axis xyz="1 0 0"/>
    <parent link="body"/>
    <child link="front_right_hip"/>
    <limit effort="100" lower="-0.78539816339744827899" upper="0.78539816339744827899" velocity="1000.00"/>
  </joint>
  <link name="front_right_upper_leg">
    <visual>
      <geometry>
        <mesh filename="package://spot_description/meshes/front_right_upper_leg.dae"/>
      </geometry>
    </visual>
    <collision>
      <geometry>
        <mesh filename="package://spot_description/meshes/front_right_upper_leg_collision.stl"/>
      </geometry>
    </collision>
    <inertial>
      <origin rpy="0 0 0" xyz="0 0 -0.14"/>
      <mass value="1.0"/>
      <inertia ixx="0.015533416666666664" ixy="0.0" ixz="0.0" iyy="0.015533416666666664" iyz="0.0" izz="0.0009626666666666666"/>
    </inertial>
  </link>
  <joint name="front_right_hip_y" type="revolute">
    <origin rpy="0 0 0" xyz="0 -0.110945 0"/>
    <axis xyz="0 1 0"/>
    <parent link="front_right_hip"/>
    <child link="front_right_upper_leg"/>
    <limit effort="100" lower="-0.89884456477707963539" upper="2.2951079663725435509" velocity="1000.00"/>
  </joint>
  <link name="front_right_lower_leg">
    <visual>
      <geometry>
        <mesh filename="package://spot_description/meshes/front_right_lower_leg.dae"/>
      </geometry>
    </visual>
    <collision>
      <geometry>
        <mesh filename="package://spot_description/meshes/front_right_lower_leg_collision.stl" scale="-1.82 0.97 0.98"/>
      </geometry>
    </collision>
    <inertial>
      <origin rpy="0 0 0" xyz="0 0 -0.16"/>
      <mass value="0.5"/>
      <inertia ixx="0.007434374999999998" ixy="0.0" ixz="0.0" iyy="0.007401041666666665" iyz="0.0" izz="0.00013541666666666666"/>
    </inertial>
  </link>
  <joint name="front_right_knee" type="revolute">
    <origin rpy="0 0 0" xyz="0.025 0 -0.3205"/>
    <axis xyz="0 1 0"/>
    <parent link="front_right_upper_leg"/>
    <child link="front_right_lower_leg"/>
    <limit effort="100" lower="-2.7929" upper="-0.254801" velocity="1000.00"/>
  </joint>
  <link name="front_right_ee"/>
  <joint name="front_right_foot" type="fixed">
    <parent link="front_right_lower_leg"/>
    <child link="front_right_ee"/>
    <origin rpy="0 0 0" xyz="0 0 -0.37"/>
  </joint>
  <link name="rear_left_hip">
    <visual>
      <geometry>
        <mesh filename="package://spot_description/meshes/rear_left_hip.dae"/>
      </geometry>
    </visual>
    <collision>
      <geometry>
        <mesh filename="package://spot_description/meshes/rear_left_hip_collision.stl"/>
      </geometry>
    </collision>
    <inertial>
      <mass value="2.0"/>
      <inertia ixx="0.0026999999999999997" ixy="0.0" ixz="0.0" iyy="0.004166666666666667" iyz="0.0" izz="0.004166666666666667"/>
    </inertial>
  </link>
  <joint name="rear_left_hip_x" type="revolute">
    <origin rpy="0 0 0" xyz="-0.29785 0.055 0"/>
    <axis xyz="1 0 0"/>
    <parent link="body"/>
    <child link="rear_left_hip"/>
    <limit effort="100" lower="-0.78539816339744827899" upper="0.78539816339744827899" velocity="1000.00"/>
  </joint>
  <link name="rear_left_upper_leg">
    <visual>
      <geometry>
        <mesh filename="package://spot_description/meshes/rear_left_upper_leg.dae"/>
      </geometry>
    </visual>
    <collision>
      <geometry>
        <mesh filename="package://spot_description/meshes/rear_left_upper_leg_collision.stl"/>
      </geometry>
    </collision>
    <inertial>
      <origin rpy="0 0 0" xyz="0 0 -0.14"/>
      <mass value="1.0"/>
      <inertia ixx="0.015533416666666664" ixy="0.0" ixz="0.0" iyy="0.015533416666666664" iyz="0.0" izz="0.0009626666666666666"/>
    </inertial>
  </link>
  <joint name="rear_left_hip_y" type="revolute">
    <origin rpy="0 0 0" xyz="0 0.110945 0"/>
    <axis xyz="0 1 0"/>
    <parent link="rear_left_hip"/>
    <child link="rear_left_upper_leg"/>
    <limit effort="100" lower="-0.89884456477707963539" upper="2.2951079663725435509" velocity="1000.00"/>
  </joint>
  <link name="rear_left_lower_leg">
    <visual>
      <geometry>
        <mesh filename="package://spot_description/meshes/rear_left_lower_leg.dae"/>
      </geometry>
    </visual>
    <collision>
      <geometry>
        <mesh filename="package://spot_description/meshes/rear_left_lower_leg_collision.stl" scale="-1.82 0.97 0.98"/>
      </geometry>
    </collision>
    <inertial>
      <origin rpy="0 0 0" xyz="0 0 -0.16"/>
      <mass value="0.5"/>
      <inertia ixx="0.007434374999999998" ixy="0.0" ixz="0.0" iyy="0.007401041666666665" iyz="0.0" izz="0.00013541666666666666"/>
    </inertial>
  </link>
  <joint name="rear_left_knee" type="revolute">
    <origin rpy="0 0 0" xyz="0.025 0 -0.3205"/>
    <axis xyz="0 1 0"/>
    <parent link="rear_left_upper_leg"/>
    <child link="rear_left_lower_leg"/>
    <limit effort="100" lower="-2.7929" upper="-0.254801" velocity="1000.00"/>
  </joint>
  <link name="rear_left_ee"/>
  <joint name="rear_left_foot" type="fixed">
    <parent link="rear_left_lower_leg"/>
    <child link="rear_left_ee"/>
    <origin rpy="0 0 0" xyz="0 0 -0.37"/>
  </joint>
  <link name="rear_right_hip">
    <visual>
      <geometry>
        <mesh filename="package://spot_description/meshes/rear_right_hip.dae"/>
      </geometry>
    </visual>
    <collision>
      <geometry>
        <mesh filename="package://spot_description/meshes/rear_right_hip_collision.stl"/>
      </geometry>
    </collision>
    <inertial>
      <mass value="2.0"/>
      <inertia ixx="0.0026999999999999997" ixy="0.0" ixz="0.0" iyy="0.004166666666666667" iyz="0.0" izz="0.004166666666666667"/>
    </inertial>
  </link>
  <joint name="rear_right_hip_x" type="revolute">
    <origin rpy="0 0 0" xyz="-0.29785 -0.055 0"/>
    <axis xyz="1 0 0"/>
    <parent link="body"/>
    <child link="rear_right_hip"/>
    <limit effort="100" lower="-0.78539816339744827899" upper="0.78539816339744827899" velocity="1000.00"/>
  </joint>
  <link name="rear_right_upper_leg">
    <visual>
      <geometry>
        <mesh filename="package://spot_description/meshes/rear_right_upper_leg.dae"/>
      </geometry>
    </visual>
    <collision>
      <geometry>
        <mesh filename="package://spot_description/meshes/rear_right_upper_leg_collision.stl"/>
      </geometry>
    </collision>
    <inertial>
      <origin rpy="0 0 0" xyz="0 0 -0.14"/>
      <mass value="1.0"/>
      <inertia ixx="0.015533416666666664" ixy="0.0" ixz="0.0" iyy="0.015533416666666664" iyz="0.0" izz="0.0009626666666666666"/>
    </inertial>
  </link>
  <joint name="rear_right_hip_y" type="revolute">
    <origin rpy="0 0 0" xyz="0 -0.110945 0"/>
    <axis xyz="0 1 0"/>
    <parent link="rear_right_hip"/>
    <child link="rear_right_upper_leg"/>
    <limit effort="100" lower="-0.89884456477707963539" upper="2.2951079663725435509" velocity="1000.00"/>
  </joint>
  <link name="rear_right_lower_leg">
    <visual>
      <geometry>
        <mesh filename="package://spot_description/meshes/rear_right_lower_leg.dae"/>
      </geometry>
    </visual>
    <collision>
      <geometry>
        <mesh filename="package://spot_description/meshes/rear_right_lower_leg_collision.stl" scale="-1.82 0.97 0.98"/>
      </geometry>
    </collision>
    <inertial>
      <origin rpy="0 0 0" xyz="0 0 -0.16"/>
      <mass value="0.5"/>
      <inertia ixx="0.007434374999999998" ixy="0.0" ixz="0.0" iyy="0.007401041666666665" iyz="0.0" izz="0.00013541666666666666"/>
    </inertial>
  </link>
  <joint name="rear_right_knee" type="revolute">
    <origin rpy="0 0 0" xyz="0.025 0 -0.3205"/>
    <axis xyz="0 1 0"/>
    <parent link="rear_right_upper_leg"/>
    <child link="rear_right_lower_leg"/>
    <limit effort="100" lower="-2.7929" upper="-0.254801" velocity="1000.00"/>
  </joint>
  <link name="rear_right_ee"/>
  <joint name="rear_right_foot" type="fixed">
    <parent link="rear_right_lower_leg"/>
    <child link="rear_right_ee"/>
    <origin rpy="0 0 0" xyz="0 0 -0.37"/>
  </joint>
</robot>
